{
 "cells": [
  {
   "cell_type": "markdown",
   "metadata": {},
   "source": [
    "# LSTM Models\n",
    "\n",
    "Created: 2019.10.18\n",
    "Notebook sequence: 8\n",
    "\n",
    "For experimenting with keras lstm models\n",
    "\n",
    "---"
   ]
  },
  {
   "cell_type": "code",
   "execution_count": 1,
   "metadata": {},
   "outputs": [],
   "source": [
    "%load_ext autoreload\n",
    "%autoreload 2"
   ]
  },
  {
   "cell_type": "code",
   "execution_count": 31,
   "metadata": {},
   "outputs": [],
   "source": [
    "import util\n",
    "import pandas as pd\n",
    "import keras\n",
    "import numpy as np\n",
    "from keras.layers import LSTM, TimeDistributed, Dense\n",
    "from sklearn.model_selection import train_test_split"
   ]
  },
  {
   "cell_type": "code",
   "execution_count": 8,
   "metadata": {},
   "outputs": [],
   "source": [
    "data = util.load_dataset(\"os_reliable_w2v/sequence.pkl\")\n",
    "df = util.load_selection_dataset(\"os_reliability.csv\")"
   ]
  },
  {
   "cell_type": "code",
   "execution_count": 23,
   "metadata": {},
   "outputs": [],
   "source": [
    "y = list(df.reliable)\n",
    "X = data\n",
    "X_train, X_valid, Y_train, Y_valid = train_test_split(X,y, test_size=0.20, random_state=13)\n",
    "X_train"
   ]
  },
  {
   "cell_type": "code",
   "execution_count": 34,
   "metadata": {},
   "outputs": [],
   "source": [
    "model = keras.Sequential()\n",
    "model.add(LSTM(32, return_sequences=True, input_shape=(None, 300)))\n",
    "model.add(TimeDistributed(Dense(2, activation='sigmoid')))"
   ]
  },
  {
   "cell_type": "code",
   "execution_count": 37,
   "metadata": {},
   "outputs": [
    {
     "ename": "ValueError",
     "evalue": "Error when checking model input: the list of Numpy arrays that you are passing to your model is not the size the model expected. Expected to see 1 array(s), but instead got the following list of 7481 arrays: [array([[-0.03759766,  0.02539062,  0.10253906, ...,  0.00124359,\n         0.1328125 ,  0.30078125],\n       [ 0.00704956, -0.07324219,  0.171875  , ...,  0.01123047,\n         0.1640625 ,  0.10693359],...",
     "output_type": "error",
     "traceback": [
      "\u001b[0;31m---------------------------------------------------------------------------\u001b[0m",
      "\u001b[0;31mValueError\u001b[0m                                Traceback (most recent call last)",
      "\u001b[0;32m<ipython-input-37-abf0e57c04f6>\u001b[0m in \u001b[0;36m<module>\u001b[0;34m\u001b[0m\n\u001b[1;32m      1\u001b[0m \u001b[0mmodel\u001b[0m\u001b[0;34m.\u001b[0m\u001b[0mcompile\u001b[0m\u001b[0;34m(\u001b[0m\u001b[0moptimizer\u001b[0m\u001b[0;34m=\u001b[0m\u001b[0;34m'adam'\u001b[0m\u001b[0;34m,\u001b[0m \u001b[0mloss\u001b[0m\u001b[0;34m=\u001b[0m\u001b[0;34m'categorical_crossentropy'\u001b[0m\u001b[0;34m)\u001b[0m\u001b[0;34m\u001b[0m\u001b[0;34m\u001b[0m\u001b[0m\n\u001b[0;32m----> 2\u001b[0;31m \u001b[0mmodel\u001b[0m\u001b[0;34m.\u001b[0m\u001b[0mfit\u001b[0m\u001b[0;34m(\u001b[0m\u001b[0mX_train\u001b[0m\u001b[0;34m,\u001b[0m \u001b[0mY_train\u001b[0m\u001b[0;34m)\u001b[0m\u001b[0;34m\u001b[0m\u001b[0;34m\u001b[0m\u001b[0m\n\u001b[0m",
      "\u001b[0;32m/usr/lib/python3.7/site-packages/keras/engine/training.py\u001b[0m in \u001b[0;36mfit\u001b[0;34m(self, x, y, batch_size, epochs, verbose, callbacks, validation_split, validation_data, shuffle, class_weight, sample_weight, initial_epoch, steps_per_epoch, validation_steps, validation_freq, max_queue_size, workers, use_multiprocessing, **kwargs)\u001b[0m\n\u001b[1;32m   1152\u001b[0m             \u001b[0msample_weight\u001b[0m\u001b[0;34m=\u001b[0m\u001b[0msample_weight\u001b[0m\u001b[0;34m,\u001b[0m\u001b[0;34m\u001b[0m\u001b[0;34m\u001b[0m\u001b[0m\n\u001b[1;32m   1153\u001b[0m             \u001b[0mclass_weight\u001b[0m\u001b[0;34m=\u001b[0m\u001b[0mclass_weight\u001b[0m\u001b[0;34m,\u001b[0m\u001b[0;34m\u001b[0m\u001b[0;34m\u001b[0m\u001b[0m\n\u001b[0;32m-> 1154\u001b[0;31m             batch_size=batch_size)\n\u001b[0m\u001b[1;32m   1155\u001b[0m \u001b[0;34m\u001b[0m\u001b[0m\n\u001b[1;32m   1156\u001b[0m         \u001b[0;31m# Prepare validation data.\u001b[0m\u001b[0;34m\u001b[0m\u001b[0;34m\u001b[0m\u001b[0;34m\u001b[0m\u001b[0m\n",
      "\u001b[0;32m/usr/lib/python3.7/site-packages/keras/engine/training.py\u001b[0m in \u001b[0;36m_standardize_user_data\u001b[0;34m(self, x, y, sample_weight, class_weight, check_array_lengths, batch_size)\u001b[0m\n\u001b[1;32m    577\u001b[0m             \u001b[0mfeed_input_shapes\u001b[0m\u001b[0;34m,\u001b[0m\u001b[0;34m\u001b[0m\u001b[0;34m\u001b[0m\u001b[0m\n\u001b[1;32m    578\u001b[0m             \u001b[0mcheck_batch_axis\u001b[0m\u001b[0;34m=\u001b[0m\u001b[0;32mFalse\u001b[0m\u001b[0;34m,\u001b[0m  \u001b[0;31m# Don't enforce the batch size.\u001b[0m\u001b[0;34m\u001b[0m\u001b[0;34m\u001b[0m\u001b[0m\n\u001b[0;32m--> 579\u001b[0;31m             exception_prefix='input')\n\u001b[0m\u001b[1;32m    580\u001b[0m \u001b[0;34m\u001b[0m\u001b[0m\n\u001b[1;32m    581\u001b[0m         \u001b[0;32mif\u001b[0m \u001b[0my\u001b[0m \u001b[0;32mis\u001b[0m \u001b[0;32mnot\u001b[0m \u001b[0;32mNone\u001b[0m\u001b[0;34m:\u001b[0m\u001b[0;34m\u001b[0m\u001b[0;34m\u001b[0m\u001b[0m\n",
      "\u001b[0;32m/usr/lib/python3.7/site-packages/keras/engine/training_utils.py\u001b[0m in \u001b[0;36mstandardize_input_data\u001b[0;34m(data, names, shapes, check_batch_axis, exception_prefix)\u001b[0m\n\u001b[1;32m    107\u001b[0m                 \u001b[0;34m'Expected to see '\u001b[0m \u001b[0;34m+\u001b[0m \u001b[0mstr\u001b[0m\u001b[0;34m(\u001b[0m\u001b[0mlen\u001b[0m\u001b[0;34m(\u001b[0m\u001b[0mnames\u001b[0m\u001b[0;34m)\u001b[0m\u001b[0;34m)\u001b[0m \u001b[0;34m+\u001b[0m \u001b[0;34m' array(s), '\u001b[0m\u001b[0;34m\u001b[0m\u001b[0;34m\u001b[0m\u001b[0m\n\u001b[1;32m    108\u001b[0m                 \u001b[0;34m'but instead got the following list of '\u001b[0m \u001b[0;34m+\u001b[0m\u001b[0;34m\u001b[0m\u001b[0;34m\u001b[0m\u001b[0m\n\u001b[0;32m--> 109\u001b[0;31m                 str(len(data)) + ' arrays: ' + str(data)[:200] + '...')\n\u001b[0m\u001b[1;32m    110\u001b[0m         \u001b[0;32melif\u001b[0m \u001b[0mlen\u001b[0m\u001b[0;34m(\u001b[0m\u001b[0mnames\u001b[0m\u001b[0;34m)\u001b[0m \u001b[0;34m>\u001b[0m \u001b[0;36m1\u001b[0m\u001b[0;34m:\u001b[0m\u001b[0;34m\u001b[0m\u001b[0;34m\u001b[0m\u001b[0m\n\u001b[1;32m    111\u001b[0m             raise ValueError(\n",
      "\u001b[0;31mValueError\u001b[0m: Error when checking model input: the list of Numpy arrays that you are passing to your model is not the size the model expected. Expected to see 1 array(s), but instead got the following list of 7481 arrays: [array([[-0.03759766,  0.02539062,  0.10253906, ...,  0.00124359,\n         0.1328125 ,  0.30078125],\n       [ 0.00704956, -0.07324219,  0.171875  , ...,  0.01123047,\n         0.1640625 ,  0.10693359],..."
     ]
    }
   ],
   "source": [
    "model.compile(optimizer='adam', loss='categorical_crossentropy')\n",
    "model.fit(X_train, Y_train)"
   ]
  }
 ],
 "metadata": {
  "kernelspec": {
   "display_name": "Python 3",
   "language": "python",
   "name": "python3"
  },
  "language_info": {
   "codemirror_mode": {
    "name": "ipython",
    "version": 3
   },
   "file_extension": ".py",
   "mimetype": "text/x-python",
   "name": "python",
   "nbconvert_exporter": "python",
   "pygments_lexer": "ipython3",
   "version": "3.7.4"
  }
 },
 "nbformat": 4,
 "nbformat_minor": 4
}
